<?xml version="1.0" ?>
<!-- =================================================================================== -->
<!-- |    This document was autogenerated by xacro from hc10dt.xacro                   | -->
<!-- |    EDITING THIS FILE BY HAND IS NOT RECOMMENDED                                 | -->
<!-- =================================================================================== -->
<robot name="motoman_hc20">

  <!-- Define the world link -->
  <link name="world"/>
  <link name="base"/>

  <!-- Base Link -->
  <link name="base_link">
    <visual>
      <geometry>
          <mesh filename="package://hc20_moveit_config/meshesvisual/base_link.stl"/>
      </geometry>
      <material name="">
        <color rgba="0.12941176470588237 0.14901960784313725 0.7490196078431373 1.0"/>
      </material>
    </visual>
    <collision>
      <geometry>
          <mesh filename="package://hc20_moveit_config/meshes/collision/base_link.stl"/>
      </geometry>
    </collision>
  </link>

  <!-- Robot Links -->
  <link name="link_1">
    <visual>
      <geometry>
          <mesh filename="package://hc20_moveit_config/meshes/visual/link_1_s.stl"/>
      </geometry>
      <material name="">
        <color rgba="0.12941176470588237 0.14901960784313725 0.7490196078431373 1.0"/>
      </material>
    </visual>
    <collision>
      <geometry>
          <mesh filename="package://hc20_moveit_config/meshes/collision/link_1_s.stl"/>
      </geometry>
    </collision>
  </link>

  <link name="link_2">
    <visual>
      <geometry>
          <mesh filename="package://hc20_moveit_config/meshes/visual/link_2_l.stl"/>
      </geometry>
      <material name="">
        <color rgba="0.12941176470588237 0.14901960784313725 0.7490196078431373 1.0"/>
      </material>
    </visual>
    <collision>
      <geometry>
          <mesh filename="package://hc20_moveit_config/meshes/collision/link_2_l.stl"/>
      </geometry>
    </collision>
  </link>

  <link name="link_3">
    <visual>
      <geometry>
          <mesh filename="package://hc20_moveit_config/meshes/visual/link_3_u.stl"/>
      </geometry>
      <material name="">
        <color rgba="0.12941176470588237 0.14901960784313725 0.7490196078431373 1.0"/>
      </material>
    </visual>
    <collision>
      <geometry>
          <mesh filename="package://hc20_moveit_config/meshes/collision/link_3_u.stl"/>
      </geometry>
    </collision>
  </link>

  <link name="link_4">
    <visual>
      <geometry>
          <mesh filename="package://hc20_moveit_config/meshes/visual/link_4_r.stl"/>
      </geometry>
      <material name="">
        <color rgba="0.12941176470588237 0.14901960784313725 0.7490196078431373 1.0"/>
      </material>
    </visual>
    <collision>
      <geometry>
          <mesh filename="package://hc20_moveit_config/meshes/collision/link_4_r.stl"/>
      </geometry>
    </collision>
  </link>

  <link name="link_5">
    <visual>
      <geometry>
          <mesh filename="package://hc20_moveit_config/meshes/visual/link_5_b.stl"/>
      </geometry>
      <material name="">
        <color rgba="0.12941176470588237 0.14901960784313725 0.7490196078431373 1.0"/>
      </material>
    </visual>
    <collision>
      <geometry>
          <mesh filename="package://hc20_moveit_config/meshes/collision/link_5_b.stl"/>
      </geometry>
    </collision>
  </link>

  <link name="link_6">
    <visual>
      <geometry>
          <mesh filename="package://hc20_moveit_config/meshes/visual/link_6_t.stl"/>
      </geometry>
      <material name="">
        <color rgba="0.12941176470588237 0.14901960784313725 0.7490196078431373 1.0"/>
      </material>
    </visual>
    <collision>
      <geometry>
          <mesh filename="package://hc20_moveit_config/meshes/collision/link_6_t.stl"/>
      </geometry>
    </collision>
  </link>

  <link name="tool0"/>

  <!-- World to Base Link -->
  <joint name="world_to_base_link" type="fixed">
    <parent link="world"/>
    <child link="base_link"/>
    <origin rpy="0 0 0" xyz="0 0 0.380"/>
  </joint>

  <joint name="base_link-base" type="fixed">
    <parent link="base_link"/>
    <child link="base"/>
    <origin rpy="0 0 0" xyz="0 0 0.380"/>
  </joint>

  <!-- Joint Definitions -->
  <joint name="joint_1" type="revolute">
    <parent link="base_link"/>
    <child link="link_1"/>
    <origin rpy="0 0 0" xyz="0 0 0.380"/>
    <axis xyz="0 0 1"/>
    <limit effort="368.48" lower="-3.141592653589793" upper="3.141592653589793" velocity="2.2689280275926285"/>
  </joint>

  <joint name="joint_2" type="revolute">
    <parent link="link_1"/>
    <child link="link_2"/>
    <origin rpy="0 0 0" xyz="0 0 0"/>
    <axis xyz="0 1 0"/>
    <limit effort="368.48" lower="-3.141592653589793" upper="3.141592653589793" velocity="2.2689280275926285"/>
  </joint>

  <joint name="joint_3" type="revolute">
    <parent link="link_2"/>
    <child link="link_3"/>
    <origin rpy="0 0 0" xyz="0 0 0.820"/>
    <axis xyz="0 -1 0"/>
    <limit effort="141.12" lower="-0.08726646259971647" upper="6.19591884457987" velocity="3.141592653589793"/>
  </joint>

  <joint name="joint_4" type="revolute">
    <parent link="link_3"/>
    <child link="link_4"/>
    <origin rpy="0 0 0" xyz="0.880 0 0"/>
    <axis xyz="-1 0 0"/>
    <limit effort="39.20" lower="-3.141592653589793" upper="3.141592653589793" velocity="3.141592653589793"/>
  </joint>

  <joint name="joint_5" type="revolute">
    <parent link="link_4"/>
    <child link="link_5"/>
    <origin rpy="0 0 0" xyz="0 0 0"/>
    <axis xyz="0 -1 0"/>
    <limit effort="31.36" lower="-3.141592653589793" upper="3.141592653589793" velocity="4.363323129985824"/>
  </joint>

  <joint name="joint_6" type="revolute">
    <parent link="link_5"/>
    <child link="link_6"/>
    <origin rpy="0 0 0" xyz="0 0 0"/>
    <axis xyz="-1 0 0"/>
    <limit effort="31.36" lower="-3.141592653589793" upper="3.141592653589793" velocity="4.363323129985824"/>
  </joint>

  <joint name="joint_6-tool0" type="fixed">
    <origin rpy="3.141592653589793 0 0" xyz="0 0 -0.170"/>
    <parent link="link_6"/>
    <child link="tool0"/>
  </joint>

</robot>