<?xml version="1.0" ?>
<robot xmlns:xacro="http://ros.org/wiki/xacro">
  <xacro:macro name="motoman_hc10dt" params="prefix">
    <xacro:include filename="$(find hc10_moveit_config)/urdf/common_materials.xacro"/>

    <!-- link list -->
    <link name="${prefix}base_link">
      <visual>
        <geometry>
          <mesh filename="package://hc20_moveit_config/meshes/visual/base_link.stl"/>
        </geometry>
        <xacro:material_yaskawa_blue/>
      </visual>
      <collision>
        <geometry>
          <mesh filename="package://hc20_moveit_config/meshes/collision/base_link.stl"/>
        </geometry>
      </collision>
    </link>
    <link name="${prefix}link_1">
      <visual>
        <geometry>
          <mesh filename="package://hc20_moveit_config/meshes/visual/link_1_s.stl"/>
        </geometry>
        <xacro:material_yaskawa_blue/>
      </visual>
      <collision>
        <geometry>
          <mesh filename="package://hc20_moveit_config/meshes/collision/link_1_s.stl"/>
        </geometry>
      </collision>
    </link>
    <link name="${prefix}link_2">
      <visual>
        <geometry>
          <mesh filename="package://hc20_moveit_config/meshes/visual/link_2_l.stl"/>
        </geometry>
        <xacro:material_yaskawa_blue/>
      </visual>
      <collision>
        <geometry>
          <mesh filename="package://hc20_moveit_config/meshes/collision/link_2_l.stl"/>
        </geometry>
      </collision>
    </link>
    <link name="${prefix}link_3">
      <visual>
        <geometry>
          <mesh filename="package://hc20_moveit_config/meshes/visual/link_3_u.stl"/>
        </geometry>
        <xacro:material_yaskawa_blue/>
      </visual>
      <collision>
        <geometry>
          <mesh filename="package://hc20_moveit_config/meshes/collision/link_3_u.stl"/>
        </geometry>
      </collision>
    </link>
    <link name="${prefix}link_4">
      <visual>
        <geometry>
          <mesh filename="package://hc20_moveit_config/meshes/visual/link_4_r.stl"/>
        </geometry>
        <xacro:material_yaskawa_blue/>
      </visual>
      <collision>
        <geometry>
          <mesh filename="package://hc20_moveit_config/meshes/collision/link_4_r.stl"/>
        </geometry>
      </collision>
    </link>
    <link name="${prefix}link_5">
      <visual>
        <geometry>
          <mesh filename="package://hc20_moveit_config/meshes/visual/link_5_b.dae"/>
        </geometry>
        <xacro:material_yaskawa_blue/>
      </visual>
      <collision>
        <geometry>
          <mesh filename="package://hc20_moveit_config/meshes/collision/link_5_b.stl"/>
        </geometry>
      </collision>
    </link>
    <link name="${prefix}link_6">
      <visual>
        <geometry>
          <mesh filename="package://hc20_moveit_config/meshes/visual/link_6_t.dae"/>
        </geometry>
        <xacro:material_yaskawa_blue/>
      </visual>
      <collision>
        <geometry>
          <mesh filename="package://hc20_moveit_config/meshes/collision/link_6_t.stl"/>
       </geometry>
      </collision>
    </link>
    <link name="${prefix}tool0"/>
    <!-- end of link list -->

    <!-- joint list -->
    <joint name="${prefix}joint_1" type="revolute">
      <parent link="${prefix}base_link"/>
      <child link="${prefix}link_1"/>
      <origin xyz="0 0 0.380" rpy="0 0 0" />
      <axis xyz="0 0 1" />
      <limit lower="${radians(-210)}" upper="${radians(210)}" effort="917.28" velocity="${radians(80)}"/>
    </joint>
    <joint name="${prefix}joint_2" type="revolute">
      <parent link="${prefix}link_1"/>
      <child link="${prefix}link_2"/>
      <origin xyz="0 0 0" rpy="0 0 0" />
      <axis xyz="0 1 0" />
      <limit lower="${radians(-180)}" upper="${radians(180)}" effort="1223.04" velocity="${radians(80)}"/>
    </joint>
    <joint name="${prefix}joint_3" type="revolute">
      <parent link="${prefix}link_2"/>
      <child link="${prefix}link_3"/>
      <origin xyz="0 0 0.820" rpy="0 0 0" />
      <axis xyz="0 -1 0" />
      <limit lower="${radians(-67)}" upper="${radians(247)}" effort="642.88" velocity="${radians(120)}"/>
    </joint>
    <joint name="${prefix}joint_4" type="revolute">
      <parent link="${prefix}link_3"/>
      <child link="${prefix}link_4"/>
      <origin xyz="0.880 0 0" rpy="0 0 0" />
      <axis xyz="-1 0 0" />
      <limit lower="${radians(-210)}" upper="${radians(210)}" effort="368.48" velocity="${radians(130)}"/>
    </joint>
    <joint name="${prefix}joint_5" type="revolute">
      <parent link="${prefix}link_4"/>
      <child link="${prefix}link_5"/>
      <origin xyz="0 0 0" rpy="0 0 0" />
      <axis xyz="0 -1 0" />
      <limit lower="${radians(-180)}" upper="${radians(180)}" effort="141.12" velocity="${radians(180)}"/>
    </joint>
    <joint name="${prefix}joint_6" type="revolute">
      <parent link="${prefix}link_5"/>
      <child link="${prefix}link_6"/>
      <origin xyz="0 0 0" rpy="0 0 0" />
      <axis xyz="-1 0 0" />
      <limit lower="${radians(-210)}" upper="${radians(210)}" effort="141.12" velocity="${radians(180)}"/>
    </joint>
    <joint name="${prefix}joint_6-tool0" type="fixed">
      <origin xyz="0.200 0 0" rpy="${radians(180)} ${radians(-90)} 0"/>
      <parent link="${prefix}link_6"/>
      <child link="${prefix}tool0"/>
    </joint>
    <!-- end of joint list -->

    <!-- ROS base_link to Robot Manufacturer World Coordinates transform -->
    <link name="${prefix}base" />
    <joint name="${prefix}base_link-base" type="fixed">
      <origin xyz="0 0 0.0.380" rpy="0 0 0"/>
      <parent link="${prefix}base_link"/>
      <child link="${prefix}base"/>
    </joint>
  </xacro:macro>
</robot>
